Workbook

Sheet Dashboard
A1: Synapse AI: Progress Dashboard
A2: Life Care Diagnostics | Synapse AI R&D / Proof of Concept only | Synthetic data only, no real patient data
A4: Report date (as of) | B4: 46323 | C4: Prepared by | D4: Tejaswi Gawai, IT Software & Application Specialist
A5: Overall status (RAG) | B5: Amber
A6: Summary for this update | B6: Baseline extractor, tests and documentation are organised and committed locally (10 of 10 tests; 17 of 17 files on known synthetic layouts, preliminary). GitHub push is pending authentication. Next: push, strengthen validation, cross-check the answer key, then research OCR and LLM options. LLM and OCR work also waits on hardware and API-budget decisions.
A9: Total tasks | B9: Done | C9: In progress | D9: Not started | E9: Blocked / hold | F9: Overall % done
A10: =SUMPRODUCT((LEFT(Plan!$A$6:$A$60,1)<>"P")*(Plan!$A$6:$A$60<>"")) -> 30 | B10: =SUMPRODUCT((LEFT(Plan!$A$6:$A$60,1)<>"P")*(Plan!$A$6:$A$60<>"")*(Plan!$G$6:$G$60="Done")) -> 8 | C10: =SUMPRODUCT((LEFT(Plan!$A$6:$A$60,1)<>"P")*(Plan!$A$6:$A$60<>"")*(Plan!$G$6:$G$60="In Progress")) -> 2 | D10: =SUMPRODUCT((LEFT(Plan!$A$6:$A$60,1)<>"P")*(Plan!$A$6:$A$60<>"")*(Plan!$G$6:$G$60="Not Started")) -> 20 | E10: =SUMPRODUCT((LEFT(Plan!$A$6:$A$60,1)<>"P")*(Plan!$A$6:$A$60<>"")*((Plan!$G$6:$G$60="Blocked")+(Plan!$G$6:$G$60="On Hold"))) -> 0 | F10: =IF(A10=0,0,SUMPRODUCT((LEFT(Plan!$A$6:$A$60,1)<>"P")*(Plan!$A$6:$A$60<>"")*Plan!$H$6:$H$60)/A10) -> 0.31833333
A12: Progress by phase
A13: Phase | B13: Start | C13: Target End | D13: % Complete | E13: Status | F13: Tasks done
A14: =Plan!B6 -> PHASE 0: Requirements and Design | B14: =Plan!D6 -> 46287 | C14: =Plan!E6 -> 46297 | D14: =Plan!H6 -> 1 | E14: =Plan!G6 -> Done | F14: =COUNTIF(Plan!G7:G8,"Done")&" of "&ROWS(Plan!G7:G8) -> 2 of 2
A15: =Plan!B9 -> PHASE 1: Baseline POC (rule-based) | B15: =Plan!D9 -> 46317 | C15: =Plan!E9 -> 46325 | D15: =Plan!H9 -> 0.97142857 | E15: =Plan!G9 -> In Progress | F15: =COUNTIF(Plan!G10:G16,"Done")&" of "&ROWS(Plan!G10:G16) -> 6 of 7
A16: =Plan!B17 -> PHASE 2: Validate and harden the baseline | B16: =Plan!D17 -> 46323 | C16: =Plan!E17 -> 46337 | D16: =Plan!H17 -> 0.15 | E16: =Plan!G17 -> In Progress | F16: =COUNTIF(Plan!G18:G22,"Done")&" of "&ROWS(Plan!G18:G22) -> 0 of 5
A17: =Plan!B23 -> PHASE 3: LLM extraction | B17: =Plan!D23 -> 46323 | C17: =Plan!E23 -> 46360 | D17: =Plan!H23 -> 0 | E17: =Plan!G23 -> Not Started | F17: =COUNTIF(Plan!G24:G28,"Done")&" of "&ROWS(Plan!G24:G28) -> 0 of 5
A18: =Plan!B29 -> PHASE 4: OCR for scanned reports | B18: =Plan!D29 -> 46363 | C18: =Plan!E29 -> 46374 | D18: =Plan!H29 -> 0 | E18: =Plan!G29 -> Not Started | F18: =COUNTIF(Plan!G30:G31,"Done")&" of "&ROWS(Plan!G30:G31) -> 0 of 2
A19: =Plan!B32 -> PHASE 5: Application build | B19: =Plan!D32 -> 46377 | C19: =Plan!E32 -> 46416 | D19: =Plan!H32 -> 0 | E19: =Plan!G32 -> Not Started | F19: =COUNTIF(Plan!G33:G37,"Done")&" of "&ROWS(Plan!G33:G37) -> 0 of 5
A20: =Plan!B38 -> PHASE 6: Test, review and demo | B20: =Plan!D38 -> 46419 | C20: =Plan!E38 -> 46437 | D20: =Plan!H38 -> 0 | E20: =Plan!G38 -> Not Started | F20: =COUNTIF(Plan!G39:G42,"Done")&" of "&ROWS(Plan!G39:G42) -> 0 of 4
A23: Decisions and approvals needed
A24: Decision / approval | B24: Needed from | D24: Status | E24: Remarks
A25: Development machine upgrade (or a shared development machine) | B25: Manager | D25: Open | E25: Current laptop: 8 GB RAM, limited disk.
A26: LLM API budget with a monthly spending cap | B26: Manager | D26: Open | E26: Cloud LLM is the likely route for the next phase.
A27: Data policy: may real patient data go to an external LLM, or stay in-house? | B27: Management / Compliance | D27: Open | E27: Synthetic data only until decided.
A28: Nominate a clinician to review extracted data and AI output | B28: Management | D28: Open
A29: Which date drives a patient timeline: collected, registered or reported? | B29: Clinical / Operations | D29: Open | E29: Source reports use different date labels.
A31: Blue text on light-blue cells = type here. Everything else updates from the Plan sheet. Figures from the baseline evaluation are on known synthetic layouts and are not an accuracy estimate for real reports.

Sheet Plan
A1: Synapse AI: Project Plan and Gantt
A2: Indicative schedule (one developer, part-time, excluding holidays and leave). Dates are estimates pending management approval and move as decisions arrive.
B3: Gantt starts on (Monday): | C3: 46286 | D3: Today: | E3: =TODAY() -> 46323
L4: Done | O4: In progress | R4: Planned | U4: Blocked | X4: On hold | AA4: Current week
A5: ID | B5: Task | C5: Owner | D5: Start Date | E5: Target End | F5: Work Days | G5: Status | H5: % Done | I5: Actual Completion | J5: Remarks / Evidence | L5: =$C$3 -> 46286 | M5: =L5+7 -> 46293 | N5: =M5+7 -> 46300 | O5: =N5+7 -> 46307 | P5: =O5+7 -> 46314 | Q5: =P5+7 -> 46321 | R5: =Q5+7 -> 46328 | S5: =R5+7 -> 46335 | T5: =S5+7 -> 46342 | ... AH5: =AG5+7 -> 46440
A6: P0 | B6: PHASE 0: Requirements and Design | D6: =MIN(D7:D8) -> 46287 | E6: =MAX(E7:E8) -> 46297 | F6: =NETWORKDAYS(D6,E6) -> 9 | G6: =IF(H6=1,"Done",IF(COUNTIF(G7:G8,"Blocked")>0,"Blocked",IF(AND(H6=0,COUNTIF(G7:G8,"In Progress")=0),"Not Started","In Progress"))) -> Done | H6: =AVERAGE(H7:H8) -> 1
A7: 0.1 | B7: R&D requirement study and system flow report | C7: Tejaswi | D7: 46287 | E7: 46297 | F7: =IF(OR(D7="",E7=""),"",NETWORKDAYS(D7,E7)) -> 9 | G7: Done | H7: 1 | I7: 46297 | J7: Report and flowchart delivered (file dated 02/10/2026).
A8: 0.2 | B8: Clickable wireframe (six screens) | C8: Tejaswi | D8: 46297 | E8: 46297 | F8: =IF(OR(D8="",E8=""),"",NETWORKDAYS(D8,E8)) -> 1 | G8: Done | H8: 1 | I8: 46297 | J8: Dashboard, Upload, Review, Library, Timeline, AI Assistant. Synthetic data only.
A9: P1 | B9: PHASE 1: Baseline POC (rule-based) | D9: =MIN(D10:D16) -> 46317 | E9: =MAX(E10:E16) -> 46325 | F9: =NETWORKDAYS(D9,E9) -> 7 | G9: =IF(H9=1,"Done",IF(COUNTIF(G10:G16,"Blocked")>0,"Blocked",IF(AND(H9=0,COUNTIF(G10:G16,"In Progress")=0),"Not Started","In Progress"))) -> In Progress | H9: =AVERAGE(H10:H16) -> 0.97142857
A10: 1.1 | B10: Workspace audit | C10: Tejaswi | D10: 46317 | E10: 46317 | F10: =IF(OR(D10="",E10=""),"",NETWORKDAYS(D10,E10)) -> 1 | G10: Done | H10: 1 | I10: 46317 | J10: PROJECT_STATUS.md created.
A11: 1.2 | B11: Define structured data schema | C11: Tejaswi | D11: 46317 | E11: 46317 | F11: =IF(OR(D11="",E11=""),"",NETWORKDAYS(D11,E11)) -> 1 | G11: Done | H11: 1 | I11: 46317 | J11: schema.py and schema.md.
A12: 1.3 | B12: Synthetic test set and answer key (10 text, 5 PDF, 2 incomplete files) | C12: Tejaswi | D12: 46317 | E12: 46317 | F12: =IF(OR(D12="",E12=""),"",NETWORKDAYS(D12,E12)) -> 1 | G12: Done | H12: 1 | I12: 46317 | J12: Answer key was drafted by AI; full cross-check is task 2.1.
A13: 1.4 | B13: Document readers (text and digital PDF) | C13: Tejaswi | D13: 46317 | E13: 46317 | F13: =IF(OR(D13="",E13=""),"",NETWORKDAYS(D13,E13)) -> 1 | G13: Done | H13: 1 | I13: 46317 | J13: 4 of 4 reader tests passed.
A14: 1.5 | B14: Rule-based extractor, validation and JSON output | C14: Tejaswi | D14: 46317 | E14: 46317 | F14: =IF(OR(D14="",E14=""),"",NETWORKDAYS(D14,E14)) -> 1 | G14: Done | H14: 1 | I14: 46317 | J14: 10 of 10 tests passed; 17 JSON files saved.
A15: 1.6 | B15: Evaluation on synthetic set | C15: Tejaswi | D15: 46317 | E15: 46317 | F15: =IF(OR(D15="",E15=""),"",NETWORKDAYS(D15,E15)) -> 1 | G15: Done | H15: 1 | I15: 46317 | J15: 17 of 17 files, 352 of 352 checked fields on known layouts. Optimistic: built on the same documents.
A16: 1.7 | B16: Source control: GitHub organisation and repository | C16: Tejaswi | D16: 46323 | E16: 46325 | F16: =IF(OR(D16="",E16=""),"",NETWORKDAYS(D16,E16)) -> 3 | G16: In Progress | H16: 0.8 | J16: Repo structure, .gitignore, .env.example and local-path handling done; committed on main, remote set. GitHub authentication and push pending.
A17: P2 | B17: PHASE 2: Validate and harden the baseline | D17: =MIN(D18:D22) -> 46323 | E17: =MAX(E18:E22) -> 46337 | F17: =NETWORKDAYS(D17,E17) -> 11 | G17: =IF(H17=1,"Done",IF(COUNTIF(G18:G22,"Blocked")>0,"Blocked",IF(AND(H17=0,COUNTIF(G18:G22,"In Progress")=0),"Not Started","In Progress"))) -> In Progress | H17: =AVERAGE(H18:H22) -> 0.15
A18: 2.1 | B18: Cross-check answer key against all source files | C18: Tejaswi | D18: 46323 | E18: 46324 | F18: =IF(OR(D18="",E18=""),"",NETWORKDAYS(D18,E18)) -> 2 | G18: Not Started | H18: 0 | J18: Verification script prepared.
A19: 2.2 | B19: Test on unseen report layouts | C19: Tejaswi | D19: 46324 | E19: 46330 | F19: =IF(OR(D19="",E19=""),"",NETWORKDAYS(D19,E19)) -> 5 | G19: Not Started | H19: 0 | J19: Expected to reveal failures; this is the honest accuracy picture.
A20: 2.3 | B20: Fix failures and re-evaluate | C20: Tejaswi | D20: 46330 | E20: 46337 | F20: =IF(OR(D20="",E20=""),"",NETWORKDAYS(D20,E20)) -> 6 | G20: Not Started | H20: 0
A21: 2.4 | B21: README, setup guide and security notes | C21: Tejaswi | D21: 46323 | E21: 46332 | F21: =IF(OR(D21="",E21=""),"",NETWORKDAYS(D21,E21)) -> 8 | G21: In Progress | H21: 0.75 | J21: README and project docs (scope, architecture, schema, evaluation, setup, roadmap) done. Security notes still to be added.
A22: 2.5 | B22: Strengthen validation logic (unrecognised tests, missing units, ambiguous values, error flagging) | C22: Tejaswi | D22: 46331 | E22: 46337 | F22: =IF(OR(D22="",E22=""),"",NETWORKDAYS(D22,E22)) -> 5 | G22: Not Started | H22: 0 | J22: Confidence thresholds apply once an LLM extractor exists; the rule-based baseline has no confidence score.
A23: P3 | B23: PHASE 3: LLM extraction | D23: =MIN(D24:D28) -> 46323 | E23: =MAX(E24:E28) -> 46360 | F23: =NETWORKDAYS(D23,E23) -> 28 | G23: =IF(H23=1,"Done",IF(COUNTIF(G24:G28,"Blocked")>0,"Blocked",IF(AND(H23=0,COUNTIF(G24:G28,"In Progress")=0),"Not Started","In Progress"))) -> Not Started | H23: =AVERAGE(H24:H28) -> 0
A24: 3.1 | B24: Development machine upgrade (or shared machine) | C24: Management | D24: 46323 | E24: 46332 | F24: =IF(OR(D24="",E24=""),"",NETWORKDAYS(D24,E24)) -> 8 | G24: Not Started | H24: 0 | J24: Request prepared; update when sent or approved. Needed before local models or OCR.
A25: 3.2 | B25: LLM API budget and data-policy decision | C25: Management / Compliance | D25: 46323 | E25: 46332 | F25: =IF(OR(D25="",E25=""),"",NETWORKDAYS(D25,E25)) -> 8 | G25: Not Started | H25: 0 | J25: Real patient data must not go to an external LLM until approved.
A26: 3.3 | B26: Choose approach: cloud API vs local open-source model | C26: Tejaswi | D26: 46335 | E26: 46339 | F26: =IF(OR(D26="",E26=""),"",NETWORKDAYS(D26,E26)) -> 5 | G26: Not Started | H26: 0 | J26: Depends on 3.1 and 3.2.
A27: 3.4 | B27: Implement LLM extractor behind the existing interface | C27: Tejaswi | D27: 46342 | E27: 46353 | F27: =IF(OR(D27="",E27=""),"",NETWORKDAYS(D27,E27)) -> 10 | G27: Not Started | H27: 0
A28: 3.5 | B28: Benchmark LLM vs baseline (accuracy, speed, cost) | C28: Tejaswi | D28: 46356 | E28: 46360 | F28: =IF(OR(D28="",E28=""),"",NETWORKDAYS(D28,E28)) -> 5 | G28: Not Started | H28: 0 | J28: Include the unseen-layout set.
A29: P4 | B29: PHASE 4: OCR for scanned reports | D29: =MIN(D30:D31) -> 46363 | E29: =MAX(E30:E31) -> 46374 | F29: =NETWORKDAYS(D29,E29) -> 10 | G29: =IF(H29=1,"Done",IF(COUNTIF(G30:G31,"Blocked")>0,"Blocked",IF(AND(H29=0,COUNTIF(G30:G31,"In Progress")=0),"Not Started","In Progress"))) -> Not Started | H29: =AVERAGE(H30:H31) -> 0
A30: 4.1 | B30: Select OCR tool suited to the hardware | C30: Tejaswi | D30: 46363 | E30: 46365 | F30: =IF(OR(D30="",E30=""),"",NETWORKDAYS(D30,E30)) -> 3 | G30: Not Started | H30: 0
A31: 4.2 | B31: Integrate OCR and test on scan-like samples | C31: Tejaswi | D31: 46366 | E31: 46374 | F31: =IF(OR(D31="",E31=""),"",NETWORKDAYS(D31,E31)) -> 7 | G31: Not Started | H31: 0
A32: P5 | B32: PHASE 5: Application build | D32: =MIN(D33:D37) -> 46377 | E32: =MAX(E33:E37) -> 46416 | F32: =NETWORKDAYS(D32,E32) -> 30 | G32: =IF(H32=1,"Done",IF(COUNTIF(G33:G37,"Blocked")>0,"Blocked",IF(AND(H32=0,COUNTIF(G33:G37,"In Progress")=0),"Not Started","In Progress"))) -> Not Started | H32: =AVERAGE(H33:H37) -> 0
A33: 5.1 | B33: Database and upload API | C33: Tejaswi | D33: 46377 | E33: 46387 | F33: =IF(OR(D33="",E33=""),"",NETWORKDAYS(D33,E33)) -> 9 | G33: Not Started | H33: 0
A34: 5.2 | B34: Review screen | C34: Tejaswi | D34: 46391 | E34: 46395 | F34: =IF(OR(D34="",E34=""),"",NETWORKDAYS(D34,E34)) -> 5 | G34: Not Started | H34: 0 | J34: Human check of extracted values against the original.
A35: 5.3 | B35: Report library and search | C35: Tejaswi | D35: 46398 | E35: 46402 | F35: =IF(OR(D35="",E35=""),"",NETWORKDAYS(D35,E35)) -> 5 | G35: Not Started | H35: 0
A36: 5.4 | B36: Patient timeline | C36: Tejaswi | D36: 46405 | E36: 46409 | F36: =IF(OR(D36="",E36=""),"",NETWORKDAYS(D36,E36)) -> 5 | G36: Not Started | H36: 0 | J36: Needs a decision on which date to use (collected, registered or reported).
A37: 5.5 | B37: AI summary with source citations | C37: Tejaswi | D37: 46412 | E37: 46416 | F37: =IF(OR(D37="",E37=""),"",NETWORKDAYS(D37,E37)) -> 5 | G37: Not Started | H37: 0
A38: P6 | B38: PHASE 6: Test, review and demo | D38: =MIN(D39:D42) -> 46419 | E38: =MAX(E39:E42) -> 46437 | F38: =NETWORKDAYS(D38,E38) -> 15 | G38: =IF(H38=1,"Done",IF(COUNTIF(G39:G42,"Blocked")>0,"Blocked",IF(AND(H38=0,COUNTIF(G39:G42,"In Progress")=0),"Not Started","In Progress"))) -> Not Started | H38: =AVERAGE(H39:H42) -> 0
A39: 6.1 | B39: End-to-end testing and bug fixes | C39: Tejaswi | D39: 46419 | E39: 46423 | F39: =IF(OR(D39="",E39=""),"",NETWORKDAYS(D39,E39)) -> 5 | G39: Not Started | H39: 0
A40: 6.2 | B40: Clinician review of extracted data and AI output | C40: Clinical reviewer | D40: 46426 | E40: 46430 | F40: =IF(OR(D40="",E40=""),"",NETWORKDAYS(D40,E40)) -> 5 | G40: Not Started | H40: 0 | J40: A reviewer needs to be nominated.
...

Sheet Daily Update
A1: Daily Update Log
A2: One row per task worked on each day. Pick the Task ID and the task name fills in. Mark whether it was done today, and note what was not done.
A4: Date | B4: Task ID | C4: Task (auto) | D4: Done today? | E4: What was done | F4: What was not done / blocker | G4: Plan for next day | H4: Evidence / link
A5: 46297 | B5: 0.1 | C5: =IF(B5="","",IFERROR(INDEX(Plan!$B$6:$B$60,MATCH(B5,Plan!$A$6:$A$60,0)),"ID not found")) -> R&D requirement study and system flow report | D5: Yes | E5: R&D requirement and system flow report prepared.
A6: 46297 | B6: 0.2 | C6: =IF(B6="","",IFERROR(INDEX(Plan!$B$6:$B$60,MATCH(B6,Plan!$A$6:$A$60,0)),"ID not found")) -> Clickable wireframe (six screens) | D6: Yes | E6: Six-screen clickable wireframe built.
A7: 46317 | B7: 1.1 | C7: =IF(B7="","",IFERROR(INDEX(Plan!$B$6:$B$60,MATCH(B7,Plan!$A$6:$A$60,0)),"ID not found")) -> Workspace audit | D7: Yes | E7: Workspace audit completed; PROJECT_STATUS.md created.
A8: 46317 | B8: 1.2 | C8: =IF(B8="","",IFERROR(INDEX(Plan!$B$6:$B$60,MATCH(B8,Plan!$A$6:$A$60,0)),"ID not found")) -> Define structured data schema | D8: Yes | E8: Structured data schema defined (schema.py, schema.md).
A9: 46317 | B9: 1.3 | C9: =IF(B9="","",IFERROR(INDEX(Plan!$B$6:$B$60,MATCH(B9,Plan!$A$6:$A$60,0)),"ID not found")) -> Synthetic test set and answer key (10 text, 5 PDF, 2 incomplete files) | D9: Yes | E9: 10 text files, 5 PDFs and 2 incomplete files prepared, with an answer key. | F9: Answer key not yet cross-checked against all source files.
A10: 46317 | B10: 1.4 | C10: =IF(B10="","",IFERROR(INDEX(Plan!$B$6:$B$60,MATCH(B10,Plan!$A$6:$A$60,0)),"ID not found")) -> Document readers (text and digital PDF) | D10: Yes | E10: Text and digital PDF readers built; 4 of 4 tests passed.
A11: 46317 | B11: 1.5 | C11: =IF(B11="","",IFERROR(INDEX(Plan!$B$6:$B$60,MATCH(B11,Plan!$A$6:$A$60,0)),"ID not found")) -> Rule-based extractor, validation and JSON output | D11: Yes | E11: Rule-based extractor and validator built; 10 of 10 tests passed; 17 JSON files saved.
A12: 46317 | B12: 1.6 | C12: =IF(B12="","",IFERROR(INDEX(Plan!$B$6:$B$60,MATCH(B12,Plan!$A$6:$A$60,0)),"ID not found")) -> Evaluation on synthetic set | D12: Yes | E12: Evaluation run: 17 of 17 files, 352 of 352 checked fields on known layouts. | F12: Unseen layouts not tested yet. | G12: Cross-check answer key; test unseen layouts.
A13: 46323 | B13: 1.7 | C13: =IF(B13="","",IFERROR(INDEX(Plan!$B$6:$B$60,MATCH(B13,Plan!$A$6:$A$60,0)),"ID not found")) -> Source control: GitHub organisation and repository | D13: Partly | E13: Repository structure organised; .gitignore and .env.example added; synthetic inputs, PDFs, ground truth and edge-case fixtures consolidated in the repo; path handling updated with fallback to the old workspace; remote configured; committed on main (working tree clean). | F13: GitHub authentication and push to the private repository pending. | G13: Authenticate, push, and confirm the files are visible on GitHub.
A14: 46323 | B14: 2.4 | C14: =IF(B14="","",IFERROR(INDEX(Plan!$B$6:$B$60,MATCH(B14,Plan!$A$6:$A$60,0)),"ID not found")) -> README, setup guide and security notes | D14: Partly | E14: README and project documentation written: scope, architecture, schema, evaluation results, setup and roadmap. | F14: Security notes still to be added. | G14: Add security notes; review docs once.
A15: 46323 | B15: 1.6 | C15: =IF(B15="","",IFERROR(INDEX(Plan!$B$6:$B$60,MATCH(B15,Plan!$A$6:$A$60,0)),"ID not found")) -> Evaluation on synthetic set | D15: Yes | E15: Re-ran tests and benchmark after the restructure: 10 of 10 tests passed; 17 of 17 files and 352 of 352 fields matched the ground truth. Preliminary synthetic result, not independently validated. | F15: Answer key not yet fully cross-checked against source files (task 2.1). | G15: Strengthen validation logic; cross-check answer key.
C16: =IF(B16="","",IFERROR(INDEX(Plan!$B$6:$B$60,MATCH(B16,Plan!$A$6:$A$60,0)),"ID not found"))
C17: =IF(B17="","",IFERROR(INDEX(Plan!$B$6:$B$60,MATCH(B17,Plan!$A$6:$A$60,0)),"ID not found"))
C18: =IF(B18="","",IFERROR(INDEX(Plan!$B$6:$B$60,MATCH(B18,Plan!$A$6:$A$60,0)),"ID not found"))
C19: =IF(B19="","",IFERROR(INDEX(Plan!$B$6:$B$60,MATCH(B19,Plan!$A$6:$A$60,0)),"ID not found"))
C20: =IF(B20="","",IFERROR(INDEX(Plan!$B$6:$B$60,MATCH(B20,Plan!$A$6:$A$60,0)),"ID not found"))
C21: =IF(B21="","",IFERROR(INDEX(Plan!$B$6:$B$60,MATCH(B21,Plan!$A$6:$A$60,0)),"ID not found"))
C22: =IF(B22="","",IFERROR(INDEX(Plan!$B$6:$B$60,MATCH(B22,Plan!$A$6:$A$60,0)),"ID not found"))
C23: =IF(B23="","",IFERROR(INDEX(Plan!$B$6:$B$60,MATCH(B23,Plan!$A$6:$A$60,0)),"ID not found"))
C24: =IF(B24="","",IFERROR(INDEX(Plan!$B$6:$B$60,MATCH(B24,Plan!$A$6:$A$60,0)),"ID not found"))
C25: =IF(B25="","",IFERROR(INDEX(Plan!$B$6:$B$60,MATCH(B25,Plan!$A$6:$A$60,0)),"ID not found"))
C26: =IF(B26="","",IFERROR(INDEX(Plan!$B$6:$B$60,MATCH(B26,Plan!$A$6:$A$60,0)),"ID not found"))
C27: =IF(B27="","",IFERROR(INDEX(Plan!$B$6:$B$60,MATCH(B27,Plan!$A$6:$A$60,0)),"ID not found"))
... C200: =IF(B200="","",IFERROR(INDEX(Plan!$B$6:$B$60,MATCH(B200,Plan!$A$6:$A$60,0)),"ID not found"))

Sheet How to Use
A1: How to use this tracker
A2: Scope: this tracker covers the Synapse AI project only. Other work is tracked separately.
A3: Daily (about 2 minutes)
A4: 1. Daily Update sheet: add a row for each task you worked on. Pick the Task ID, set 'Done today?' to Yes, Partly or No, and write what was not done or what is blocking it.
A5: 2. Plan sheet: update Status and % Done for tasks that changed. When a task finishes, set Status to Done, % Done to 100% and fill in Actual Completion.
A6: 3. Dashboard: update the report date, the overall status (Green, Amber or Red) and the one-paragraph summary. Everything else updates itself.
A7: 4. Save with the date in the file name (for example Synapse_Progress_2026-10-28.xlsx) before emailing it.
A9: Reading the Gantt chart (Plan sheet)
A10: Each column is one week, starting on the Monday in cell C3. Bars show the Start Date to Target End of each task. Green = done, amber = in progress, blue = planned, red = blocked, grey = on hold. The red week header and pale yellow column mark the current week.
A11: A Target End date turns red when the task is overdue and not Done.
A13: Which cells to edit
A14: Dashboard: blue text on light-blue cells. Plan: ID, Task, Owner, dates, Status, % Done, Actual Completion and Remarks. Phase rows (dark blue) and the Work Days column calculate themselves. Daily Update: every column except 'Task (auto)'.
... A20: The 17 of 17 evaluation result is on known synthetic layouts and is not an accuracy estimate for real reports. All data used is synthetic.
